[2022-07-03 16:24:16,329] {taskinstance.py:1159} INFO - Dependencies all met for <TaskInstance: my_bash_operator_dag.second_task manual__2022-07-03T16:24:14.905202+00:00 [queued]>
[2022-07-03 16:24:16,335] {taskinstance.py:1159} INFO - Dependencies all met for <TaskInstance: my_bash_operator_dag.second_task manual__2022-07-03T16:24:14.905202+00:00 [queued]>
[2022-07-03 16:24:16,335] {taskinstance.py:1356} INFO - 
--------------------------------------------------------------------------------
[2022-07-03 16:24:16,335] {taskinstance.py:1357} INFO - Starting attempt 1 of 1
[2022-07-03 16:24:16,335] {taskinstance.py:1358} INFO - 
--------------------------------------------------------------------------------
[2022-07-03 16:24:16,348] {taskinstance.py:1377} INFO - Executing <Task(BashOperator): second_task> on 2022-07-03 16:24:14.905202+00:00
[2022-07-03 16:24:16,350] {standard_task_runner.py:52} INFO - Started process 2502 to run task
[2022-07-03 16:24:16,352] {standard_task_runner.py:79} INFO - Running: ['***', 'tasks', 'run', 'my_bash_operator_dag', 'second_task', 'manual__2022-07-03T16:24:14.905202+00:00', '--job-id', '195', '--raw', '--subdir', 'DAGS_FOLDER/my_bash_operator_dag.py', '--cfg-path', '/tmp/tmp8rau0trl', '--error-file', '/tmp/tmpuyxthit7']
[2022-07-03 16:24:16,353] {standard_task_runner.py:80} INFO - Job 195: Subtask second_task
[2022-07-03 16:24:16,387] {task_command.py:370} INFO - Running <TaskInstance: my_bash_operator_dag.second_task manual__2022-07-03T16:24:14.905202+00:00 [running]> on host a84f4c234c47
[2022-07-03 16:24:16,443] {taskinstance.py:1571} INFO - Exporting the following env vars:
AIRFLOW_CTX_DAG_OWNER=***
AIRFLOW_CTX_DAG_ID=my_bash_operator_dag
AIRFLOW_CTX_TASK_ID=second_task
AIRFLOW_CTX_EXECUTION_DATE=2022-07-03T16:24:14.905202+00:00
AIRFLOW_CTX_TRY_NUMBER=1
AIRFLOW_CTX_DAG_RUN_ID=manual__2022-07-03T16:24:14.905202+00:00
[2022-07-03 16:24:16,443] {subprocess.py:62} INFO - Tmp dir root location: 
 /tmp
[2022-07-03 16:24:16,444] {subprocess.py:74} INFO - Running command: ['bash', '-c', 'this is a second task']
[2022-07-03 16:24:16,449] {subprocess.py:85} INFO - Output:
[2022-07-03 16:24:16,450] {subprocess.py:92} INFO - bash: line 1: this: command not found
[2022-07-03 16:24:16,450] {subprocess.py:96} INFO - Command exited with return code 127
[2022-07-03 16:24:16,460] {taskinstance.py:1889} ERROR - Task failed with exception
Traceback (most recent call last):
  File "/home/airflow/.local/lib/python3.7/site-packages/airflow/operators/bash.py", line 195, in execute
    f'Bash command failed. The command returned a non-zero exit code {result.exit_code}.'
airflow.exceptions.AirflowException: Bash command failed. The command returned a non-zero exit code 127.
[2022-07-03 16:24:16,462] {taskinstance.py:1400} INFO - Marking task as FAILED. dag_id=my_bash_operator_dag, task_id=second_task, execution_date=20220703T162414, start_date=20220703T162416, end_date=20220703T162416
[2022-07-03 16:24:16,471] {standard_task_runner.py:97} ERROR - Failed to execute job 195 for task second_task (Bash command failed. The command returned a non-zero exit code 127.; 2502)
[2022-07-03 16:24:16,483] {local_task_job.py:156} INFO - Task exited with return code 1
[2022-07-03 16:24:16,506] {local_task_job.py:273} INFO - 0 downstream tasks scheduled from follow-on schedule check
